[Fri Feb 25 23:04:40 2022] [INFO] Cogs loaded successfully
[Fri Feb 25 23:05:59 2022] [INFO] Bot initialized
[Fri Feb 25 23:06:03 2022] [INFO] Cogs loaded successfully
[Fri Feb 25 23:06:03 2022] [INFO] Latency: 200ms
[Fri Feb 25 23:07:20 2022] [INFO] Bot initialized
[Fri Feb 25 23:07:24 2022] [INFO] Cogs loaded successfully
[Fri Feb 25 23:07:24 2022] [INFO] Latency: 206ms
[Fri Feb 25 23:08:46 2022] [INFO] Bot initialized
[Fri Feb 25 23:08:50 2022] [INFO] Cogs loaded successfully
[Fri Feb 25 23:08:50 2022] [INFO] Latency: 196ms
[Fri Feb 25 23:09:13 2022] [INFO] Bot initialized
[Fri Feb 25 23:09:17 2022] [INFO] Cogs loaded successfully
[Fri Feb 25 23:09:17 2022] [INFO] Latency: 195ms
[Fri Feb 25 23:15:41 2022] [INFO] Bot initialized
[Fri Feb 25 23:15:45 2022] [INFO] Cogs loaded successfully
[Fri Feb 25 23:15:45 2022] [INFO] Latency: 197ms
[Fri Feb 25 23:21:18 2022] [INFO] Bot initialized
[Fri Feb 25 23:21:21 2022] ERROR] Traceback (most recent call last):
  File "C:\Users\osama\AppData\Local\Programs\Python\Python310\lib\importlib\util.py", line 96, in find_spec
    parent_path = parent.__path__
AttributeError: module 'src.cogs.images' has no attribute '__path__'

The above exception was the direct cause of the following exception:

Traceback (most recent call last):
  File "C:\Users\osama\PycharmProjects\Geo Bot\src\bot.py", line 23, in on_ready
    self.load_extension(f"src.cogs.{i}")
  File "C:\Users\osama\AppData\Local\Programs\Python\Python310\lib\site-packages\disnake\ext\commands\common_bot_base.py", line 486, in load_extension
    spec = importlib.util.find_spec(name)
  File "C:\Users\osama\AppData\Local\Programs\Python\Python310\lib\importlib\util.py", line 98, in find_spec
    raise ModuleNotFoundError(
ModuleNotFoundError: __path__ attribute not found on 'src.cogs.images' while trying to find 'src.cogs.images.py'

[Fri Feb 25 23:21:21 2022] [INFO] Cogs loaded successfully
[Fri Feb 25 23:21:21 2022] [INFO] Latency: 199ms
[Fri Feb 25 23:22:31 2022] [INFO] Bot initialized
[Fri Feb 25 23:22:35 2022] [INFO] Loaded images
[Fri Feb 25 23:22:35 2022] [ERROR] Traceback (most recent call last):
  File "C:\Users\osama\AppData\Local\Programs\Python\Python310\lib\site-packages\disnake\ext\commands\common_bot_base.py", line 424, in _load_from_module_spec
    setup = getattr(lib, "setup")
AttributeError: module 'src.cogs.__pycache__' has no attribute 'setup'

During handling of the above exception, another exception occurred:

Traceback (most recent call last):
  File "C:\Users\osama\PycharmProjects\Geo Bot\src\bot.py", line 24, in on_ready
    self.load_extension(f"src.cogs.{i}")
  File "C:\Users\osama\AppData\Local\Programs\Python\Python310\lib\site-packages\disnake\ext\commands\common_bot_base.py", line 490, in load_extension
    self._load_from_module_spec(spec, name)
  File "C:\Users\osama\AppData\Local\Programs\Python\Python310\lib\site-packages\disnake\ext\commands\common_bot_base.py", line 427, in _load_from_module_spec
    raise errors.NoEntryPointError(key)
disnake.ext.commands.errors.NoEntryPointError: Extension 'src.cogs.__pycache__' has no 'setup' function.

[Fri Feb 25 23:22:36 2022] [INFO] Cogs loaded successfully
[Fri Feb 25 23:22:36 2022] [INFO] Latency: 316ms
[Fri Feb 25 23:23:02 2022] [INFO] Bot initialized
[Fri Feb 25 23:23:06 2022] [INFO] Loaded images
[Fri Feb 25 23:23:06 2022] [INFO] Cogs loaded successfully
[Fri Feb 25 23:23:06 2022] [INFO] Latency: 229ms
[Fri Feb 25 23:32:54 2022] [INFO] Bot initialized
[Fri Feb 25 23:32:57 2022] [INFO] Loaded images
[Fri Feb 25 23:32:57 2022] [INFO] Cogs loaded successfully
[Fri Feb 25 23:32:57 2022] [INFO] Latency: 305ms
[Fri Feb 25 23:36:54 2022] [INFO] Bot initialized
[Fri Feb 25 23:36:58 2022] [INFO] Loaded images
[Fri Feb 25 23:36:58 2022] [INFO] Cogs loaded successfully
[Fri Feb 25 23:36:58 2022] [INFO] Latency: 318ms
[Fri Feb 25 23:37:51 2022] [INFO] Bot initialized
[Fri Feb 25 23:37:55 2022] [INFO] Loaded images
[Fri Feb 25 23:37:55 2022] [INFO] Cogs loaded successfully
[Fri Feb 25 23:37:55 2022] [INFO] Latency: 307ms
[Fri Feb 25 23:38:19 2022] [INFO] Bot initialized
[Fri Feb 25 23:38:22 2022] [INFO] Loaded images
[Fri Feb 25 23:38:22 2022] [INFO] Cogs loaded successfully
[Fri Feb 25 23:38:22 2022] [INFO] Latency: 214ms
[Fri Feb 25 23:41:57 2022] [INFO] Bot initialized
[Fri Feb 25 23:42:01 2022] [INFO] Loaded images
[Fri Feb 25 23:42:01 2022] [INFO] Cogs loaded successfully
[Fri Feb 25 23:42:01 2022] [INFO] Latency: 312ms
[Fri Feb 25 23:47:37 2022] [INFO] Bot initialized
[Fri Feb 25 23:47:41 2022] [INFO] Loaded images
[Fri Feb 25 23:47:41 2022] [INFO] Cogs loaded successfully
[Fri Feb 25 23:47:41 2022] [INFO] Latency: 197ms
[Sat Feb 26 14:54:25 2022] [ERROR] Traceback (most recent call last):
  File "C:\Users\osama\PycharmProjects\Geo Bot\src\bot.py", line 25, in on_ready
    self.load_extension(f"src.cogs.{i}")
  File "C:\Users\osama\AppData\Local\Programs\Python\Python310\lib\site-packages\disnake\ext\commands\common_bot_base.py", line 484, in load_extension
    raise errors.ExtensionAlreadyLoaded(name)
disnake.ext.commands.errors.ExtensionAlreadyLoaded: Extension 'src.cogs.images' is already loaded.

[Sat Feb 26 14:54:25 2022] [INFO] Cogs loaded successfully
[Sat Feb 26 14:54:25 2022] [INFO] Latency: 4995ms
[Sat Feb 26 17:35:22 2022] [INFO] Bot initialized
[Sat Feb 26 17:35:26 2022] [INFO] Loaded images
[Sat Feb 26 17:35:26 2022] [INFO] Loaded misc
[Sat Feb 26 17:35:26 2022] [INFO] Cogs loaded successfully
[Sat Feb 26 17:35:26 2022] [INFO] Latency: 328ms
[Sat Feb 26 17:36:23 2022] [INFO] Bot initialized
[Sat Feb 26 17:36:27 2022] [INFO] Loaded images
[Sat Feb 26 17:36:27 2022] [INFO] Loaded misc
[Sat Feb 26 17:36:27 2022] [INFO] Cogs loaded successfully
[Sat Feb 26 17:36:27 2022] [INFO] Latency: 320ms
[Sat Feb 26 17:37:25 2022] [INFO] Bot initialized
[Sat Feb 26 17:37:29 2022] [INFO] Loaded images
[Sat Feb 26 17:37:29 2022] [INFO] Loaded misc
[Sat Feb 26 17:37:29 2022] [INFO] Cogs loaded successfully
[Sat Feb 26 17:37:29 2022] [INFO] Latency: 206ms
